<?xml version="1.0" encoding="utf-8"?>

<robot name="rm_gimbal"
  xmlns:xacro="http://ros.org/wiki/xacro">

  <xacro:arg name="xyz" default="0.10 0 0.05" />
  <xacro:arg name="rpy" default="0 0 0" />

  <link name="aim_odom" />

  <link name="aim_gimbal_link" />

  <joint name="aim_gimbal_joint" type="floating">
    <parent link="aim_odom" />
    <child link="aim_gimbal_link" />
  </joint>

  <link name="aim_camera_link" />

  <joint name="aim_camera_joint" type="fixed">
    <origin xyz="$(arg xyz)" rpy="$(arg rpy)" />
    <parent link="aim_gimbal_link" />
    <child link="aim_camera_link" />
    <axis xyz="0 0 0" />
  </joint>

  <link name="aim_camera_optical_frame" />

  <joint name="aim_camera_optical_joint" type="fixed">
    <origin xyz="0 0 0" rpy="${-pi/2} 0 ${-pi/2}" />
    <parent link="aim_camera_link" />
    <child link="aim_camera_optical_frame" />
  </joint>

</robot>
